<?xml version="1.0" encoding="utf-8"?>
<!-- This URDF was automatically created by SolidWorks to URDF Exporter! Originally created by Stephen Brawner (brawner@gmail.com) 
     Commit Version: 1.6.0-4-g7f85cfe  Build Version: 1.6.7995.38578
     For more information, please see http://wiki.ros.org/sw_urdf_exporter -->
<robot
  name="crane">
<link name="base_footprint">
    <visual>
        <origin xyz="0 0 0" rpy="0 0 0" />
        <geometry>
            <box size="0.001 0.001 0.001" />
        </geometry>
    </visual>
    <collision>
	<origin xyz="0 0 0" rpy="0 0 0"/>
	<geometry>
	    <box size="0.001 0.001 0.001"/>
	</geometry>
    </collision>
</link>

<joint name="base_footprint_joint" type="fixed">
    <origin xyz="0 0 0" rpy="0 0 0" />
    <parent link="base_footprint"/>
    <child link="L1" />
</joint>
  <link
    name="L1">
    <inertial>
      <origin
        xyz="1.46240415435095E-05 0.0626523408176193 0.0183572839444473"
        rpy="0 0 0" />
      <mass
        value="2.934566665164" />
      <inertia
        ixx="0.00807653689773365"
        ixy="-1.02570316823648E-07"
        ixz="-4.44167161068851E-08"
        iyy="0.00485832414061642"
        iyz="-7.7701192203099E-06"
        izz="0.0112514186928177" />
    </inertial>
    <visual>
      <origin
        xyz="0 0 0"
        rpy="0 0 0" />
      <geometry>
        <mesh
          filename="package://uorover_arm/meshes/visual/L1.STL" />
      </geometry>
      <material
        name="">
        <color
          rgba="0.752941176470588 0.752941176470588 0.752941176470588 1" />
      </material>
    </visual>
    <collision>
      <origin
        xyz="0 0 0"
        rpy="0 0 0" />
      <geometry>
        <mesh
          filename="package://uorover_arm/meshes/collision/L1.STL" />
      </geometry>
    </collision>
  </link>
  <link
    name="L2">
    <inertial>
      <origin
        xyz="-0.00368694035818651 -3.21494672345761E-05 0.0956990751549506"
        rpy="0 0 0" />
      <mass
        value="1.18613336880623" />
      <inertia
        ixx="0.0014201652113015"
        ixy="2.76657887443281E-11"
        ixz="0.000221872575909511"
        iyy="0.00150405295307427"
        iyz="-1.28741499566648E-10"
        izz="0.00193692878914472" />
    </inertial>
    <visual>
      <origin
        xyz="0 0 0"
        rpy="0 0 0" />
      <geometry>
        <mesh
          filename="package://uorover_arm/meshes/visual/L2.STL" />
      </geometry>
      <material
        name="">
        <color
          rgba="0.752941176470588 0.752941176470588 0.752941176470588 1" />
      </material>
    </visual>
    <collision>
      <origin
        xyz="0 0 0"
        rpy="0 0 0" />
      <geometry>
        <mesh
          filename="package://uorover_arm/meshes/collision/L2.STL" />
      </geometry>
    </collision>
  </link>
  <joint
    name="q1"
    type="revolute">
    <origin
      xyz="0 0 0"
      rpy="0 0 0" />
    <parent
      link="L1" />
    <child
      link="L2" />
    <axis
      xyz="0 0 1" />
    <limit
      lower="-3.8785"
      upper="0.7624"
      effort="50.0"
      velocity="2.0" />
  </joint>
  <link
    name="L3">
    <inertial>
      <origin
        xyz="0.251575528519281 -0.00331808327790925 0.000548399832373654"
        rpy="0 0 0" />
      <mass
        value="1.07194618957619" />
      <inertia
        ixx="0.000661948351652191"
        ixy="5.98822820971425E-06"
        ixz="-3.78845293388608E-13"
        iyy="0.0201253592251019"
        iyz="-4.95492265171914E-14"
        izz="0.0199394147192728" />
    </inertial>
    <visual>
      <origin
        xyz="0 0 0"
        rpy="0 0 0" />
      <geometry>
        <mesh
          filename="package://uorover_arm/meshes/visual/L3.STL" />
      </geometry>
      <material
        name="">
        <color
          rgba="0.752941176470588 0.752941176470588 0.752941176470588 1" />
      </material>
    </visual>
    <collision>
      <origin
        xyz="0 0 0"
        rpy="0 0 0" />
      <geometry>
        <mesh
          filename="package://uorover_arm/meshes/collision/L3.STL" />
      </geometry>
    </collision>
  </link>
  <joint
    name="q2"
    type="revolute">
    <origin
      xyz="0.0068581 0 0.111"
      rpy="1.5708 -0.23274 0" />
    <parent
      link="L2" />
    <child
      link="L3" />
    <axis
      xyz="0 0 1" />
    <limit
      lower="-0.0750"
      upper="1.3500"
      effort="50.0"
      velocity="2.0" />
  </joint>
  <link
    name="L4">
    <inertial>
      <origin
        xyz="0.0720260669864247 -1.66633176990061E-06 0.00985179408803023"
        rpy="0 0 0" />
      <mass
        value="1.66772751268548" />
      <inertia
        ixx="0.00114001304274005"
        ixy="4.73348234358579E-08"
        ixz="3.86287096525101E-07"
        iyy="0.0081020495705238"
        iyz="1.02110954258301E-08"
        izz="0.00755258229148096" />
    </inertial>
    <visual>
      <origin
        xyz="0 0 0"
        rpy="0 0 0" />
      <geometry>
        <mesh
          filename="package://uorover_arm/meshes/visual/L4.STL" />
      </geometry>
      <material
        name="">
        <color
          rgba="0.752941176470588 0.752941176470588 0.752941176470588 1" />
      </material>
    </visual>
    <collision>
      <origin
        xyz="0 0 0"
        rpy="0 0 0" />
      <geometry>
        <mesh
          filename="package://uorover_arm/meshes/collision/L4.STL" />
      </geometry>
    </collision>
  </link>
  <joint
    name="q3"
    type="revolute">
    <origin
      xyz="0.5 0 0.0010984"
      rpy="0 0 -0.62654" />
    <parent
      link="L3" />
    <child
      link="L4" />
    <axis
      xyz="0 0 -1" />
    <limit
      lower="0.000"
      upper="1.7500"
      effort="50.0"
      velocity="2.0" />
  </joint>
  <link
    name="L5">
    <inertial>
      <origin
        xyz="0.159052892911078 0.00432353745129826 0.000133318231799476"
        rpy="0 0 0" />
      <mass
        value="1.65698710373046" />
      <inertia
        ixx="0.000839185518117455"
        ixy="4.25551886425564E-08"
        ixz="-1.03290465827116E-06"
        iyy="0.000970248473334317"
        iyz="1.28170604083139E-07"
        izz="0.000954020274587562" />
    </inertial>
    <visual>
      <origin
        xyz="0 0 0"
        rpy="0 0 0" />
      <geometry>
        <mesh
          filename="package://uorover_arm/meshes/visual/L5.STL" />
      </geometry>
      <material
        name="">
        <color
          rgba="0.752941176470588 0.752941176470588 0.752941176470588 1" />
      </material>
    </visual>
    <collision>
      <origin
        xyz="0 0 0"
        rpy="0 0 0" />
      <geometry>
        <mesh
          filename="package://uorover_arm/meshes/collision/L5.STL" />
      </geometry>
    </collision>
  </link>
  <joint
    name="q4"
    type="revolute">
    <origin
      xyz="0.25 0 0.00014259"
      rpy="0 0 0.3938" />
    <parent
      link="L4" />
    <child
      link="L5" />
    <axis
      xyz="0 0 -1" />
    <limit
      lower="-1.1500"
      upper="2.0000"
      effort="50.0"
      velocity="2.0" />
  </joint>
</robot>
